Workbook
Name Slicer_Destination: #N/A
Name Slicer_Travel_Month: #N/A
Name Slicer_Travel_Type: #N/A

Sheet Travel Genesis Cleaned Data
A1: Booking_ID | B1: Destination | C1: Travel_Month | D1: Price_USD | E1: Customer_Age | F1: Booking_Date | G1: Travel_Type | H1: Payment_Method | I1: Booking_Month | J1: Age_Groups
A2: e6b47fb5 | B2: London | C2: January | D2: 1905.57 | E2: 33 | F2: 45155 | G2: Business | H2: Credit Card | I2: =TEXT(Table2[[#This Row],[Booking_Date]],"mmmm") -> August | J2: =IF(Table2[[#This Row],[Customer_Age]]<20,"10-19", IF(Table2[[#This Row],[Customer_Age]]<30,"20-29", IF(Table2[[#This Row],[Customer_Age]]<40,"30-39", IF(Table2[[#This Row],[Customer_Age]]<50,"40-49", IF(Table2[[#This Row],[Customer_Age]]<60,"50-59", IF(Table2[[#This Row],[Customer_Age]]<70,"60-69","70+")))))) -> 30-39
A3: 59319d69 | B3: Bangkok | C3: February | D3: 1558.13 | E3: 20 | F3: 44957 | G3: Business | H3: PayPal | I3: =TEXT(Table2[[#This Row],[Booking_Date]],"mmmm") -> January | J3: =IF(Table2[[#This Row],[Customer_Age]]<20,"10-19", IF(Table2[[#This Row],[Customer_Age]]<30,"20-29", IF(Table2[[#This Row],[Customer_Age]]<40,"30-39", IF(Table2[[#This Row],[Customer_Age]]<50,"40-49", IF(Table2[[#This Row],[Customer_Age]]<60,"50-59", IF(Table2[[#This Row],[Customer_Age]]<70,"60-69","70+")))))) -> 20-29
A4: 30313de9 | B4: Tokyo | C4: September | D4: 1584.64 | E4: 53 | F4: 45130 | G4: Leisure | H4: PayPal | I4: =TEXT(Table2[[#This Row],[Booking_Date]],"mmmm") -> July | J4: =IF(Table2[[#This Row],[Customer_Age]]<20,"10-19", IF(Table2[[#This Row],[Customer_Age]]<30,"20-29", IF(Table2[[#This Row],[Customer_Age]]<40,"30-39", IF(Table2[[#This Row],[Customer_Age]]<50,"40-49", IF(Table2[[#This Row],[Customer_Age]]<60,"50-59", IF(Table2[[#This Row],[Customer_Age]]<70,"60-69","70+")))))) -> 50-59
A5: 8c00aa9e | B5: Toronto | C5: October | D5: 839.84 | E5: 18 | F5: 45090 | G5: Leisure | H5: Bank Transfer | I5: =TEXT(Table2[[#This Row],[Booking_Date]],"mmmm") -> June | J5: =IF(Table2[[#This Row],[Customer_Age]]<20,"10-19", IF(Table2[[#This Row],[Customer_Age]]<30,"20-29", IF(Table2[[#This Row],[Customer_Age]]<40,"30-39", IF(Table2[[#This Row],[Customer_Age]]<50,"40-49", IF(Table2[[#This Row],[Customer_Age]]<60,"50-59", IF(Table2[[#This Row],[Customer_Age]]<70,"60-69","70+")))))) -> 10-19
A6: a6ccb8e6 | B6: Dubai | C6: March | D6: 695.22 | E6: 66 | F6: 45271 | G6: Business | H6: Credit Card | I6: =TEXT(Table2[[#This Row],[Booking_Date]],"mmmm") -> December | J6: =IF(Table2[[#This Row],[Customer_Age]]<20,"10-19", IF(Table2[[#This Row],[Customer_Age]]<30,"20-29", IF(Table2[[#This Row],[Customer_Age]]<40,"30-39", IF(Table2[[#This Row],[Customer_Age]]<50,"40-49", IF(Table2[[#This Row],[Customer_Age]]<60,"50-59", IF(Table2[[#This Row],[Customer_Age]]<70,"60-69","70+")))))) -> 60-69
A7: 3a68e657 | B7: Cape Town | C7: February | D7: 1025.65 | E7: 40 | F7: 45545 | G7: Leisure | H7: Credit Card | I7: =TEXT(Table2[[#This Row],[Booking_Date]],"mmmm") -> September | J7: =IF(Table2[[#This Row],[Customer_Age]]<20,"10-19", IF(Table2[[#This Row],[Customer_Age]]<30,"20-29", IF(Table2[[#This Row],[Customer_Age]]<40,"30-39", IF(Table2[[#This Row],[Customer_Age]]<50,"40-49", IF(Table2[[#This Row],[Customer_Age]]<60,"50-59", IF(Table2[[#This Row],[Customer_Age]]<70,"60-69","70+")))))) -> 40-49
A8: 9249ccaf | B8: Toronto | C8: September | D8: 487.1 | E8: 42 | F8: 45007 | G8: Leisure | H8: Bank Transfer | I8: =TEXT(Table2[[#This Row],[Booking_Date]],"mmmm") -> March | J8: =IF(Table2[[#This Row],[Customer_Age]]<20,"10-19", IF(Table2[[#This Row],[Customer_Age]]<30,"20-29", IF(Table2[[#This Row],[Customer_Age]]<40,"30-39", IF(Table2[[#This Row],[Customer_Age]]<50,"40-49", IF(Table2[[#This Row],[Customer_Age]]<60,"50-59", IF(Table2[[#This Row],[Customer_Age]]<70,"60-69","70+")))))) -> 40-49
A9: e3e24f3b | B9: Sydney | C9: April | D9: 1820.52 | E9: 20 | F9: 45604 | G9: Business | H9: Bank Transfer | I9: =TEXT(Table2[[#This Row],[Booking_Date]],"mmmm") -> November | J9: =IF(Table2[[#This Row],[Customer_Age]]<20,"10-19", IF(Table2[[#This Row],[Customer_Age]]<30,"20-29", IF(Table2[[#This Row],[Customer_Age]]<40,"30-39", IF(Table2[[#This Row],[Customer_Age]]<50,"40-49", IF(Table2[[#This Row],[Customer_Age]]<60,"50-59", IF(Table2[[#This Row],[Customer_Age]]<70,"60-69","70+")))))) -> 20-29
A10: 4054b0b8 | B10: London | C10: April | D10: 2192.91 | E10: 42 | F10: 45211 | G10: Leisure | H10: Bank Transfer | I10: =TEXT(Table2[[#This Row],[Booking_Date]],"mmmm") -> October | J10: =IF(Table2[[#This Row],[Customer_Age]]<20,"10-19", IF(Table2[[#This Row],[Customer_Age]]<30,"20-29", IF(Table2[[#This Row],[Customer_Age]]<40,"30-39", IF(Table2[[#This Row],[Customer_Age]]<50,"40-49", IF(Table2[[#This Row],[Customer_Age]]<60,"50-59", IF(Table2[[#This Row],[Customer_Age]]<70,"60-69","70+")))))) -> 40-49
A11: d8209e8d | B11: New York | C11: June | D11: 1017.12 | E11: 60 | F11: 45200 | G11: Business | H11: PayPal | I11: =TEXT(Table2[[#This Row],[Booking_Date]],"mmmm") -> October | J11: =IF(Table2[[#This Row],[Customer_Age]]<20,"10-19", IF(Table2[[#This Row],[Customer_Age]]<30,"20-29", IF(Table2[[#This Row],[Customer_Age]]<40,"30-39", IF(Table2[[#This Row],[Customer_Age]]<50,"40-49", IF(Table2[[#This Row],[Customer_Age]]<60,"50-59", IF(Table2[[#This Row],[Customer_Age]]<70,"60-69","70+")))))) -> 60-69
A12: 92d367f6 | B12: Bangkok | C12: December | D12: 763.07 | E12: 47 | F12: 45315 | G12: Leisure | H12: PayPal | I12: =TEXT(Table2[[#This Row],[Booking_Date]],"mmmm") -> January | J12: =IF(Table2[[#This Row],[Customer_Age]]<20,"10-19", IF(Table2[[#This Row],[Customer_Age]]<30,"20-29", IF(Table2[[#This Row],[Customer_Age]]<40,"30-39", IF(Table2[[#This Row],[Customer_Age]]<50,"40-49", IF(Table2[[#This Row],[Customer_Age]]<60,"50-59", IF(Table2[[#This Row],[Customer_Age]]<70,"60-69","70+")))))) -> 40-49
A13: abc21647 | B13: Rome | C13: January | D13: 726.81 | E13: 20 | F13: 45250 | G13: Leisure | H13: Bank Transfer | I13: =TEXT(Table2[[#This Row],[Booking_Date]],"mmmm") -> November | J13: =IF(Table2[[#This Row],[Customer_Age]]<20,"10-19", IF(Table2[[#This Row],[Customer_Age]]<30,"20-29", IF(Table2[[#This Row],[Customer_Age]]<40,"30-39", IF(Table2[[#This Row],[Customer_Age]]<50,"40-49", IF(Table2[[#This Row],[Customer_Age]]<60,"50-59", IF(Table2[[#This Row],[Customer_Age]]<70,"60-69","70+")))))) -> 20-29
... A84: 9cf1a203 | B84: Paris | C84: June | D84: 886.81 | E84: 42 | F84: 45356 | G84: Business | H84: Crypto | I84: =TEXT(Table2[[#This Row],[Booking_Date]],"mmmm") -> March | J84: =IF(Table2[[#This Row],[Customer_Age]]<20,"10-19", IF(Table2[[#This Row],[Customer_Age]]<30,"20-29", IF(Table2[[#This Row],[Customer_Age]]<40,"30-39", IF(Table2[[#This Row],[Customer_Age]]<50,"40-49", IF(Table2[[#This Row],[Customer_Age]]<60,"50-59", IF(Table2[[#This Row],[Customer_Age]]<70,"60-69","70+")))))) -> 40-49
A85: 13871559 | B85: Tokyo | C85: May | D85: 1202.42 | E85: 19 | F85: 45325 | G85: Leisure | H85: Crypto | I85: =TEXT(Table2[[#This Row],[Booking_Date]],"mmmm") -> February | J85: =IF(Table2[[#This Row],[Customer_Age]]<20,"10-19", IF(Table2[[#This Row],[Customer_Age]]<30,"20-29", IF(Table2[[#This Row],[Customer_Age]]<40,"30-39", IF(Table2[[#This Row],[Customer_Age]]<50,"40-49", IF(Table2[[#This Row],[Customer_Age]]<60,"50-59", IF(Table2[[#This Row],[Customer_Age]]<70,"60-69","70+")))))) -> 10-19
A86: cb369b04 | B86: New York | C86: August | D86: 2314.95 | E86: 57 | F86: 45473 | G86: Business | H86: Crypto | I86: =TEXT(Table2[[#This Row],[Booking_Date]],"mmmm") -> June | J86: =IF(Table2[[#This Row],[Customer_Age]]<20,"10-19", IF(Table2[[#This Row],[Customer_Age]]<30,"20-29", IF(Table2[[#This Row],[Customer_Age]]<40,"30-39", IF(Table2[[#This Row],[Customer_Age]]<50,"40-49", IF(Table2[[#This Row],[Customer_Age]]<60,"50-59", IF(Table2[[#This Row],[Customer_Age]]<70,"60-69","70+")))))) -> 50-59
A87: 06c22ad7 | B87: Sydney | C87: October | D87: 1724.9 | E87: 23 | F87: 45585 | G87: Leisure | H87: PayPal | I87: =TEXT(Table2[[#This Row],[Booking_Date]],"mmmm") -> October | J87: =IF(Table2[[#This Row],[Customer_Age]]<20,"10-19", IF(Table2[[#This Row],[Customer_Age]]<30,"20-29", IF(Table2[[#This Row],[Customer_Age]]<40,"30-39", IF(Table2[[#This Row],[Customer_Age]]<50,"40-49", IF(Table2[[#This Row],[Customer_Age]]<60,"50-59", IF(Table2[[#This Row],[Customer_Age]]<70,"60-69","70+")))))) -> 20-29
A88: d31bda4f | B88: Toronto | C88: March | D88: 315.65 | E88: 42 | F88: 45262 | G88: Business | H88: Crypto | I88: =TEXT(Table2[[#This Row],[Booking_Date]],"mmmm") -> December | J88: =IF(Table2[[#This Row],[Customer_Age]]<20,"10-19", IF(Table2[[#This Row],[Customer_Age]]<30,"20-29", IF(Table2[[#This Row],[Customer_Age]]<40,"30-39", IF(Table2[[#This Row],[Customer_Age]]<50,"40-49", IF(Table2[[#This Row],[Customer_Age]]<60,"50-59", IF(Table2[[#This Row],[Customer_Age]]<70,"60-69","70+")))))) -> 40-49
A89: db2e538c | B89: Rome | C89: June | D89: 1950.83 | E89: 42 | F89: 45211 | G89: Leisure | H89: Bank Transfer | I89: =TEXT(Table2[[#This Row],[Booking_Date]],"mmmm") -> October | J89: =IF(Table2[[#This Row],[Customer_Age]]<20,"10-19", IF(Table2[[#This Row],[Customer_Age]]<30,"20-29", IF(Table2[[#This Row],[Customer_Age]]<40,"30-39", IF(Table2[[#This Row],[Customer_Age]]<50,"40-49", IF(Table2[[#This Row],[Customer_Age]]<60,"50-59", IF(Table2[[#This Row],[Customer_Age]]<70,"60-69","70+")))))) -> 40-49
A90: ec8ed2f6 | B90: London | C90: August | D90: 244.58 | E90: 52 | F90: 44980 | G90: Leisure | H90: PayPal | I90: =TEXT(Table2[[#This Row],[Booking_Date]],"mmmm") -> February | J90: =IF(Table2[[#This Row],[Customer_Age]]<20,"10-19", IF(Table2[[#This Row],[Customer_Age]]<30,"20-29", IF(Table2[[#This Row],[Customer_Age]]<40,"30-39", IF(Table2[[#This Row],[Customer_Age]]<50,"40-49", IF(Table2[[#This Row],[Customer_Age]]<60,"50-59", IF(Table2[[#This Row],[Customer_Age]]<70,"60-69","70+")))))) -> 50-59
A91: d75cd7ab | B91: London | C91: November | D91: 292.59 | E91: 19 | F91: 45180 | G91: Business | H91: Credit Card | I91: =TEXT(Table2[[#This Row],[Booking_Date]],"mmmm") -> September | J91: =IF(Table2[[#This Row],[Customer_Age]]<20,"10-19", IF(Table2[[#This Row],[Customer_Age]]<30,"20-29", IF(Table2[[#This Row],[Customer_Age]]<40,"30-39", IF(Table2[[#This Row],[Customer_Age]]<50,"40-49", IF(Table2[[#This Row],[Customer_Age]]<60,"50-59", IF(Table2[[#This Row],[Customer_Age]]<70,"60-69","70+")))))) -> 10-19
A92: d1ccbee6 | B92: Sydney | C92: March | D92: 748.65 | E92: 48 | F92: 45612 | G92: Business | H92: PayPal | I92: =TEXT(Table2[[#This Row],[Booking_Date]],"mmmm") -> November | J92: =IF(Table2[[#This Row],[Customer_Age]]<20,"10-19", IF(Table2[[#This Row],[Customer_Age]]<30,"20-29", IF(Table2[[#This Row],[Customer_Age]]<40,"30-39", IF(Table2[[#This Row],[Customer_Age]]<50,"40-49", IF(Table2[[#This Row],[Customer_Age]]<60,"50-59", IF(Table2[[#This Row],[Customer_Age]]<70,"60-69","70+")))))) -> 40-49
A93: 17b1e36e | B93: Toronto | C93: December | D93: 789.36 | E93: 41 | F93: 45098 | G93: Business | H93: PayPal | I93: =TEXT(Table2[[#This Row],[Booking_Date]],"mmmm") -> June | J93: =IF(Table2[[#This Row],[Customer_Age]]<20,"10-19", IF(Table2[[#This Row],[Customer_Age]]<30,"20-29", IF(Table2[[#This Row],[Customer_Age]]<40,"30-39", IF(Table2[[#This Row],[Customer_Age]]<50,"40-49", IF(Table2[[#This Row],[Customer_Age]]<60,"50-59", IF(Table2[[#This Row],[Customer_Age]]<70,"60-69","70+")))))) -> 40-49
A94: ef359088 | B94: Dubai | C94: February | D94: 1530.97 | E94: 37 | F94: 45516 | G94: Leisure | H94: Crypto | I94: =TEXT(Table2[[#This Row],[Booking_Date]],"mmmm") -> August | J94: =IF(Table2[[#This Row],[Customer_Age]]<20,"10-19", IF(Table2[[#This Row],[Customer_Age]]<30,"20-29", IF(Table2[[#This Row],[Customer_Age]]<40,"30-39", IF(Table2[[#This Row],[Customer_Age]]<50,"40-49", IF(Table2[[#This Row],[Customer_Age]]<60,"50-59", IF(Table2[[#This Row],[Customer_Age]]<70,"60-69","70+")))))) -> 30-39
A95: 7c81ed4e | B95: Tokyo | C95: February | D95: 1561.83 | E95: 58 | F95: 45175 | G95: Business | H95: Bank Transfer | I95: =TEXT(Table2[[#This Row],[Booking_Date]],"mmmm") -> September | J95: =IF(Table2[[#This Row],[Customer_Age]]<20,"10-19", IF(Table2[[#This Row],[Customer_Age]]<30,"20-29", IF(Table2[[#This Row],[Customer_Age]]<40,"30-39", IF(Table2[[#This Row],[Customer_Age]]<50,"40-49", IF(Table2[[#This Row],[Customer_Age]]<60,"50-59", IF(Table2[[#This Row],[Customer_Age]]<70,"60-69","70+")))))) -> 50-59
A96: f4865501 | B96: Sydney | C96: February | D96: 2031.32 | E96: 54 | F96: 44969 | G96: Leisure | H96: Crypto | I96: =TEXT(Table2[[#This Row],[Booking_Date]],"mmmm") -> February | J96: =IF(Table2[[#This Row],[Customer_Age]]<20,"10-19", IF(Table2[[#This Row],[Customer_Age]]<30,"20-29", IF(Table2[[#This Row],[Customer_Age]]<40,"30-39", IF(Table2[[#This Row],[Customer_Age]]<50,"40-49", IF(Table2[[#This Row],[Customer_Age]]<60,"50-59", IF(Table2[[#This Row],[Customer_Age]]<70,"60-69","70+")))))) -> 50-59
A97: 3b731440 | B97: Rome | C97: February | D97: 1363.71 | E97: 39 | F97: 44939 | G97: Leisure | H97: Crypto | I97: =TEXT(Table2[[#This Row],[Booking_Date]],"mmmm") -> January | J97: =IF(Table2[[#This Row],[Customer_Age]]<20,"10-19", IF(Table2[[#This Row],[Customer_Age]]<30,"20-29", IF(Table2[[#This Row],[Customer_Age]]<40,"30-39", IF(Table2[[#This Row],[Customer_Age]]<50,"40-49", IF(Table2[[#This Row],[Customer_Age]]<60,"50-59", IF(Table2[[#This Row],[Customer_Age]]<70,"60-69","70+")))))) -> 30-39
... A294: 596e8cfa | B294: Sydney | C294: August | D294: 592.18 | E294: 58 | F294: 45561 | G294: Leisure | H294: PayPal | I294: =TEXT(Table2[[#This Row],[Booking_Date]],"mmmm") -> September | J294: =IF(Table2[[#This Row],[Customer_Age]]<20,"10-19", IF(Table2[[#This Row],[Customer_Age]]<30,"20-29", IF(Table2[[#This Row],[Customer_Age]]<40,"30-39", IF(Table2[[#This Row],[Customer_Age]]<50,"40-49", IF(Table2[[#This Row],[Customer_Age]]<60,"50-59", IF(Table2[[#This Row],[Customer_Age]]<70,"60-69","70+")))))) -> 50-59

Sheet Basic EDA
B2: PRICE_USD | F2: CUSTOMER_AGE
B4: Mean | C4: 1326.0799 | F4: Mean | G4: 45.327645
B5: Standard Error | C5: 39.772856 | F5: Standard Error | G5: 0.86135347
B6: Median | C6: 1293.15 | F6: Median | G6: 47
B7: Mode | C7: No mode | F7: Mode | G7: 61
B8: Standard Deviation | C8: 680.80162 | F8: Standard Deviation | G8: 14.743996
B9: Sample Variance | C9: 463490.85 | F9: Sample Variance | G9: 217.38543
B10: Kurtosis | C10: -1.1788159 | F10: Kurtosis | G10: -1.0924044
B11: Skewness | C11: 0.080931535 | F11: Skewness | G11: -0.21070211
B12: Range | C12: 2286.27 | F12: Range | G12: 52
B13: Minimum | C13: 212.08 | F13: Minimum | G13: 18
B14: Maximum | C14: 2498.35 | F14: Maximum | G14: 70
B15: Sum | C15: 388541.41 | F15: Sum | G15: 13281
B16: Count | C16: 293 | F16: Count | G16: 293

Sheet Pivot Tables
B1: BEHAVIOUR TREND ANALYSIS - TRAVEL GENESIS
B3: PEAK BOOKING TIMES | F3: TRAVEL MONTH PREFERENCES
B4: Row Labels | C4: Count of Booking_ID | F4: Row Labels | G4: Count of Booking_ID | L4: Count of Booking_ID | M4: Column Labels
B5: January | C5: 21 | F5: January | G5: 27 | L5: Row Labels | M5: Business | N5: Leisure | O5: Grand Total
B6: February | C6: 26 | F6: February | G6: 37 | L6: January | M6: 12 | N6: 15 | O6: 27
B7: March | C7: 26 | F7: March | G7: 18 | L7: February | M7: 15 | N7: 22 | O7: 37
B8: April | C8: 32 | F8: April | G8: 24 | L8: March | M8: 9 | N8: 9 | O8: 18
B9: May | C9: 30 | F9: May | G9: 27 | L9: April | M9: 11 | N9: 13 | O9: 24
B10: June | C10: 23 | F10: June | G10: 21 | L10: May | M10: 14 | N10: 13 | O10: 27
B11: July | C11: 24 | F11: July | G11: 22 | L11: June | M11: 13 | N11: 8 | O11: 21
B12: August | C12: 16 | F12: August | G12: 24 | L12: July | M12: 8 | N12: 14 | O12: 22
B13: September | C13: 24 | F13: September | G13: 23 | L13: August | M13: 11 | N13: 13 | O13: 24
B14: October | C14: 22 | F14: October | G14: 20 | L14: September | M14: 7 | N14: 16 | O14: 23
B15: November | C15: 26 | F15: November | G15: 26 | L15: October | M15: 9 | N15: 11 | O15: 20
B16: December | C16: 23 | F16: December | G16: 24 | L16: November | M16: 13 | N16: 13 | O16: 26
B17: Grand Total | C17: 293 | F17: Grand Total | G17: 293 | L17: December | M17: 14 | N17: 10 | O17: 24
L18: Grand Total | M18: 136 | N18: 157 | O18: 293
B20: USER PREFERENCES ANALYSIS ("The Why & How")
B23: PAYMENT METHOD PREFERENCES | G23: PEAK TIMES FOR TRAVEL | L23: DESTINATION PREFERENCES BY TRAVEL TYPE
B24: Count of Booking_ID | C24: Column Labels | G24: Count of Booking_ID | H24: Column Labels | L24: Count of Booking_ID | M24: Column Labels
B25: Row Labels | C25: Business | D25: Leisure | E25: Grand Total | G25: Row Labels | H25: Business | I25: Leisure | J25: Grand Total | L25: Row Labels | M25: Business | N25: Leisure | O25: Grand Total
B26: Bank Transfer | C26: 40 | D26: 47 | E26: 87 | G26: January | H26: 12 | I26: 15 | J26: 27 | L26: Toronto | M26: 13 | N26: 22 | O26: 35
B27: Credit Card | C27: 21 | D27: 40 | E27: 61 | G27: February | H27: 15 | I27: 22 | J27: 37 | L27: Tokyo | M27: 9 | N27: 14 | O27: 23
B28: Crypto | C28: 36 | D28: 37 | E28: 73 | G28: March | H28: 9 | I28: 9 | J28: 18 | L28: Sydney | M28: 18 | N28: 22 | O28: 40
B29: PayPal | C29: 39 | D29: 33 | E29: 72 | G29: April | H29: 11 | I29: 13 | J29: 24 | L29: Rome | M29: 10 | N29: 12 | O29: 22
B30: Grand Total | C30: 136 | D30: 157 | E30: 293 | G30: May | H30: 14 | I30: 13 | J30: 27 | L30: Paris | M30: 15 | N30: 5 | O30: 20
G31: June | H31: 13 | I31: 8 | J31: 21 | L31: New York | M31: 14 | N31: 20 | O31: 34
G32: July | H32: 8 | I32: 14 | J32: 22 | L32: London | M32: 22 | N32: 19 | O32: 41
B33: Row Labels | C33: Grand Total | G33: August | H33: 11 | I33: 13 | J33: 24 | L33: Dubai | M33: 8 | N33: 12 | O33: 20
B34: Bank Transfer | C34: 87 | G34: September | H34: 7 | I34: 16 | J34: 23 | L34: Cape Town | M34: 12 | N34: 15 | O34: 27
B35: Credit Card | C35: 61 | G35: October | H35: 9 | I35: 11 | J35: 20 | L35: Bangkok | M35: 15 | N35: 16 | O35: 31
B36: Crypto | C36: 73 | G36: November | H36: 13 | I36: 13 | J36: 26 | L36: Grand Total | M36: 136 | N36: 157 | O36: 293
B37: PayPal | C37: 72 | G37: December | H37: 14 | I37: 10 | J37: 24
G38: Grand Total | H38: 136 | I38: 157 | J38: 293
E43: PHASE 2
B46: TOP DESTINATIONS BY BOOKING VOLUME | G46: TOP DESTINATIONS BY REVENUE | L46: AVERAGE BOOKING VALUE BY DESTINATION
B47: Row Labels | C47: Count of Booking_ID | G47: Row Labels | H47: Sum of Price_USD | L47: Row Labels | M47: Average of Price_USD
B48: London | C48: 41 | G48: London | H48: 56780.49 | L48: Rome | M48: 1110.2273
B49: Sydney | C49: 40 | G49: New York | H49: 48776.95 | L49: Cape Town | M49: 1174.4144
B50: Toronto | C50: 35 | G50: Sydney | H50: 48036.83 | L50: Toronto | M50: 1189.9529
...

Sheet Travel Genesis Dashboard
A1: TRAVEL GENESIS ANALYTICS OVERVIEW
